noisy hard run 1: coda_hard_p1
2020-05-25 13:57:59,162 Initializing dataset PointNav-v1
2020-05-25 13:58:01,426 Initializing dataset PointNav-v1
2020-05-25 13:58:01,427 initializing sim Sim-v0
2020-05-25 13:58:02,371 Initializing task Nav-v0
Process ForkServerProcess-1:
Traceback (most recent call last):
  File "/private/home/jtruong/.conda/envs/habitat/lib/python3.6/multiprocessing/process.py", line 258, in _bootstrap
    self.run()
  File "/private/home/jtruong/.conda/envs/habitat/lib/python3.6/multiprocessing/process.py", line 93, in run
    self._target(*self._args, **self._kwargs)
  File "/private/home/jtruong/repos/habitat-api/habitat/core/vector_env.py", line 172, in _worker_env
    env = env_fn(*env_fn_args)
  File "/private/home/jtruong/repos/habitat-api/habitat_baselines/common/env_utils.py", line 32, in make_env_fn
    env = env_class(config=config, dataset=dataset)
  File "/private/home/jtruong/repos/habitat-api/habitat_baselines/common/environments.py", line 42, in __init__
    super().__init__(self._core_env_config, dataset)
  File "/private/home/jtruong/repos/habitat-api/habitat/core/env.py", line 333, in __init__
    self._env = Env(config, dataset)
  File "/private/home/jtruong/repos/habitat-api/habitat/core/env.py", line 110, in __init__
    dataset=self._dataset,
  File "/private/home/jtruong/repos/habitat-api/habitat/tasks/registration.py", line 21, in make_task
    return _task(**kwargs)
  File "/private/home/jtruong/repos/habitat-api/habitat/tasks/nav/nav.py", line 1119, in __init__
    super().__init__(config=config, sim=sim, dataset=dataset)
  File "/private/home/jtruong/repos/habitat-api/habitat/core/embodied_task.py", line 241, in __init__
    entities_config=config,
  File "/private/home/jtruong/repos/habitat-api/habitat/core/embodied_task.py", line 277, in _init_entities
    task=self,
TypeError: __init__() got an unexpected keyword argument 'dataset'
Traceback (most recent call last):
  File "evaluation/evaluate_simulation_coda.py", line 488, in <module>
    main()
  File "evaluation/evaluate_simulation_coda.py", line 213, in main
    envs = construct_envs(config, get_env_class(config.ENV_NAME))
  File "/private/home/jtruong/repos/habitat-api/habitat_baselines/common/env_utils.py", line 101, in construct_envs
    tuple(zip(configs, env_classes, range(num_processes)))
  File "/private/home/jtruong/repos/habitat-api/habitat/core/vector_env.py", line 140, in __init__
    read_fn() for read_fn in self._connection_read_fns
  File "/private/home/jtruong/repos/habitat-api/habitat/core/vector_env.py", line 140, in <listcomp>
    read_fn() for read_fn in self._connection_read_fns
  File "/private/home/jtruong/.conda/envs/habitat/lib/python3.6/multiprocessing/connection.py", line 250, in recv
    buf = self._recv_bytes()
  File "/private/home/jtruong/.conda/envs/habitat/lib/python3.6/multiprocessing/connection.py", line 407, in _recv_bytes
    buf = self._recv(4)
  File "/private/home/jtruong/.conda/envs/habitat/lib/python3.6/multiprocessing/connection.py", line 379, in _recv
    chunk = read(handle, remaining)
ConnectionResetError: [Errno 104] Connection reset by peer
Exception ignored in: <bound method VectorEnv.__del__ of <habitat.core.vector_env.VectorEnv object at 0x7fb3a062dc50>>
Traceback (most recent call last):
  File "/private/home/jtruong/repos/habitat-api/habitat/core/vector_env.py", line 518, in __del__
    self.close()
  File "/private/home/jtruong/repos/habitat-api/habitat/core/vector_env.py", line 400, in close
    write_fn((CLOSE_COMMAND, None))
  File "/private/home/jtruong/.conda/envs/habitat/lib/python3.6/multiprocessing/connection.py", line 206, in send
    self._send_bytes(_ForkingPickler.dumps(obj))
  File "/private/home/jtruong/.conda/envs/habitat/lib/python3.6/multiprocessing/connection.py", line 404, in _send_bytes
    self._send(header + buf)
  File "/private/home/jtruong/.conda/envs/habitat/lib/python3.6/multiprocessing/connection.py", line 368, in _send
    n = write(self._handle, buf)
BrokenPipeError: [Errno 32] Broken pipe
noisy hard run 2: coda_hard_p1
2020-05-25 13:58:05,137 Initializing dataset PointNav-v1
2020-05-25 13:58:07,784 Initializing dataset PointNav-v1
2020-05-25 13:58:07,787 initializing sim Sim-v0
2020-05-25 13:58:08,753 Initializing task Nav-v0
Process ForkServerProcess-1:
Traceback (most recent call last):
  File "/private/home/jtruong/.conda/envs/habitat/lib/python3.6/multiprocessing/process.py", line 258, in _bootstrap
    self.run()
  File "/private/home/jtruong/.conda/envs/habitat/lib/python3.6/multiprocessing/process.py", line 93, in run
    self._target(*self._args, **self._kwargs)
  File "/private/home/jtruong/repos/habitat-api/habitat/core/vector_env.py", line 172, in _worker_env
    env = env_fn(*env_fn_args)
  File "/private/home/jtruong/repos/habitat-api/habitat_baselines/common/env_utils.py", line 32, in make_env_fn
    env = env_class(config=config, dataset=dataset)
  File "/private/home/jtruong/repos/habitat-api/habitat_baselines/common/environments.py", line 42, in __init__
    super().__init__(self._core_env_config, dataset)
  File "/private/home/jtruong/repos/habitat-api/habitat/core/env.py", line 333, in __init__
    self._env = Env(config, dataset)
  File "/private/home/jtruong/repos/habitat-api/habitat/core/env.py", line 110, in __init__
    dataset=self._dataset,
  File "/private/home/jtruong/repos/habitat-api/habitat/tasks/registration.py", line 21, in make_task
    return _task(**kwargs)
  File "/private/home/jtruong/repos/habitat-api/habitat/tasks/nav/nav.py", line 1119, in __init__
    super().__init__(config=config, sim=sim, dataset=dataset)
  File "/private/home/jtruong/repos/habitat-api/habitat/core/embodied_task.py", line 241, in __init__
    entities_config=config,
  File "/private/home/jtruong/repos/habitat-api/habitat/core/embodied_task.py", line 277, in _init_entities
    task=self,
TypeError: __init__() got an unexpected keyword argument 'dataset'
Traceback (most recent call last):
  File "evaluation/evaluate_simulation_coda.py", line 488, in <module>
    main()
  File "evaluation/evaluate_simulation_coda.py", line 213, in main
    envs = construct_envs(config, get_env_class(config.ENV_NAME))
  File "/private/home/jtruong/repos/habitat-api/habitat_baselines/common/env_utils.py", line 101, in construct_envs
    tuple(zip(configs, env_classes, range(num_processes)))
  File "/private/home/jtruong/repos/habitat-api/habitat/core/vector_env.py", line 140, in __init__
    read_fn() for read_fn in self._connection_read_fns
  File "/private/home/jtruong/repos/habitat-api/habitat/core/vector_env.py", line 140, in <listcomp>
    read_fn() for read_fn in self._connection_read_fns
  File "/private/home/jtruong/.conda/envs/habitat/lib/python3.6/multiprocessing/connection.py", line 250, in recv
    buf = self._recv_bytes()
  File "/private/home/jtruong/.conda/envs/habitat/lib/python3.6/multiprocessing/connection.py", line 407, in _recv_bytes
    buf = self._recv(4)
  File "/private/home/jtruong/.conda/envs/habitat/lib/python3.6/multiprocessing/connection.py", line 379, in _recv
    chunk = read(handle, remaining)
ConnectionResetError: [Errno 104] Connection reset by peer
Exception ignored in: <bound method VectorEnv.__del__ of <habitat.core.vector_env.VectorEnv object at 0x7fe3fe17ec88>>
Traceback (most recent call last):
  File "/private/home/jtruong/repos/habitat-api/habitat/core/vector_env.py", line 518, in __del__
    self.close()
  File "/private/home/jtruong/repos/habitat-api/habitat/core/vector_env.py", line 400, in close
    write_fn((CLOSE_COMMAND, None))
  File "/private/home/jtruong/.conda/envs/habitat/lib/python3.6/multiprocessing/connection.py", line 206, in send
    self._send_bytes(_ForkingPickler.dumps(obj))
  File "/private/home/jtruong/.conda/envs/habitat/lib/python3.6/multiprocessing/connection.py", line 404, in _send_bytes
    self._send(header + buf)
  File "/private/home/jtruong/.conda/envs/habitat/lib/python3.6/multiprocessing/connection.py", line 368, in _send
    n = write(self._handle, buf)
BrokenPipeError: [Errno 32] Broken pipe
noisy hard run 3: coda_hard_p1
